<sdf version='1.7'>
  <model name='R2'>
    <link name='base_footprint'>
      <inertial>
        <pose>-0.006689 -8.5e-05 0.111489 0 -0 0</pose>
        <mass>0.72448</mass>
        <inertia>
          <ixx>0.000859465</ixx>
          <ixy>-4.82288e-07</ixy>
          <ixz>-0.000155498</ixz>
          <iyy>0.00154785</iyy>
          <iyz>-5.13752e-07</iyz>
          <izz>0.00192928</izz>
        </inertia>
      </inertial>
      <collision name='base_footprint_fixed_joint_lump__base_link_collision'>
        <pose>0 0 0.0215 0 -0 0</pose>
        <geometry>
          <mesh>
            <scale>1 1 1</scale>
            <uri>model://odap/src/r2_description/meshes/base_link.stl</uri>
          </mesh>
        </geometry>
        <surface>
          <contact>
            <ode/>
          </contact>
          <friction>
            <ode/>
          </friction>
        </surface>
      </collision>
      <collision name='base_footprint_fixed_joint_lump__base_bumper_collision_1'>
        <pose>0.0134 0 0.0615 0 -0 0</pose>
        <geometry>
          <box>
            <size>0.342 0.205 0.11</size>
          </box>
        </geometry>
        <surface>
          <contact>
            <ode/>
          </contact>
          <friction>
            <ode/>
          </friction>
        </surface>
      </collision>
      <collision name='base_footprint_fixed_joint_lump__laz_base_collision_2'>
        <pose>0.012548 0 0.1265 0 -0 0</pose>
        <geometry>
          <cylinder>
            <length>0.011</length>
            <radius>0.04</radius>
          </cylinder>
        </geometry>
        <surface>
          <contact>
            <ode/>
          </contact>
          <friction>
            <ode>
              <mu>0.2</mu>
              <mu2>0.2</mu2>
            </ode>
          </friction>
        </surface>
      </collision>
      <collision name='base_footprint_fixed_joint_lump__laz_rot_collision_3'>
        <pose>0.012548 0 0.1375 0 -0 0</pose>
        <geometry>
          <cylinder>
            <length>0.035</length>
            <radius>0.03</radius>
          </cylinder>
        </geometry>
        <surface>
          <contact>
            <ode/>
          </contact>
          <friction>
            <ode>
              <mu>0.2</mu>
              <mu2>0.2</mu2>
            </ode>
          </friction>
        </surface>
      </collision>
      <visual name='base_footprint_fixed_joint_lump__base_link_visual'>
        <pose>0 0 0.0215 0 -0 0</pose>
        <geometry>
          <mesh>
            <scale>1 1 1</scale>
            <uri>model://odap/src/r2_description/meshes/base_link.stl</uri>
          </mesh>
        </geometry>
        <material>
          <script>
            <name>Gazebo/Green</name>
            <uri>file://media/materials/scripts/gazebo.material</uri>
          </script>
        </material>
      </visual>
      <visual name='base_footprint_fixed_joint_lump__laz_base_visual_1'>
        <pose>0.012548 0 0.1265 0 -0 0</pose>
        <geometry>
          <cylinder>
            <length>0.011</length>
            <radius>0.04</radius>
          </cylinder>
        </geometry>
        <material>
          <script>
            <name>Gazebo/Grey</name>
            <uri>file://media/materials/scripts/gazebo.material</uri>
          </script>
        </material>
      </visual>
      <visual name='base_footprint_fixed_joint_lump__laz_rot_visual_2'>
        <pose>0.012548 0 0.1375 0 -0 0</pose>
        <geometry>
          <cylinder>
            <length>0.035</length>
            <radius>0.03</radius>
          </cylinder>
        </geometry>
        <material>
          <script>
            <name>Gazebo/RedGlow</name>
            <uri>file://media/materials/scripts/gazebo.material</uri>
          </script>
        </material>
      </visual>
      <sensor name='main_bumper' type='contact'>
        <always_on>1</always_on>
        <update_rate>15</update_rate>
        <contact>
          <collision>base_link_collision_base_bumper</collision>
          <topic>__default_topic__</topic>
        </contact>
        <plugin name='gazebo_ros_bumper_controller' filename='libgazebo_ros_bumper.so'>
          <bumperTopicName>/R2/bumper</bumperTopicName>
          <frameName>world</frameName>
        </plugin>
        <pose>0.0134 0 0.0615 0 -0 0</pose>
      </sensor>
      <sensor name='laz' type='ray'>
        <always_on>1</always_on>
        <visualize>1</visualize>
        <update_rate>10</update_rate>
        <ray>
          <scan>
            <horizontal>
              <samples>281</samples>
              <resolution>1</resolution>
              <min_angle>-3.14159</min_angle>
              <max_angle>3.14159</max_angle>
            </horizontal>
          </scan>
          <range>
            <min>0.15</min>
            <max>12</max>
            <resolution>0.015</resolution>
          </range>
        </ray>
        <plugin name='gazebo_ros_laser_controller' filename='libgazebo_ros_laser.so'>
          <topicName>/R2/laser/scan</topicName>
          <frameName>laz_rot</frameName>
          <updateRate>6.0</updateRate>
          <minRange>0.15</minRange>
          <maxRange>12.0</maxRange>
          <noise>
            <type>gaussian</type>
            <mean>0.0</mean>
            <stddev>0.01</stddev>
          </noise>
        </plugin>
        <pose>0.012548 0 0.1375 0 -0 0</pose>
        <noise>
          <type>gaussian</type>
          <mean>0.0</mean>
          <stddev>0.01</stddev>
        </noise>
      </sensor>
    </link>
    <joint name='left_rear_axle' type='revolute'>
      <pose relative_to='base_footprint'>-0.11607 0.08425 0.034 0 -0 0</pose>
      <parent>base_footprint</parent>
      <child>left_rear_wheel</child>
      <axis>
        <xyz>0 1 0</xyz>
        <limit>
          <lower>-1e+16</lower>
          <upper>1e+16</upper>
        </limit>
        <dynamics>
          <spring_reference>0</spring_reference>
          <spring_stiffness>0</spring_stiffness>
        </dynamics>
      </axis>
    </joint>
    <link name='left_rear_wheel'>
      <pose relative_to='left_rear_axle'>0 0 0 0 -0 0</pose>
      <inertial>
        <pose>0 0 0 1.5708 -0 0</pose>
        <mass>1</mass>
        <inertia>
          <ixx>9.62948e-05</ixx>
          <ixy>0</ixy>
          <ixz>0</ixz>
          <iyy>0.000578</iyy>
          <iyz>0</iyz>
          <izz>9.62948e-05</izz>
        </inertia>
      </inertial>
      <collision name='left_rear_wheel_collision'>
        <pose>0 0 0 1.5708 -0 0</pose>
        <geometry>
          <cylinder>
            <length>0.0267</length>
            <radius>0.034</radius>
          </cylinder>
        </geometry>
        <surface>
          <contact>
            <ode/>
          </contact>
          <friction>
            <ode/>
          </friction>
        </surface>
      </collision>
      <visual name='left_rear_wheel_visual'>
        <pose>0 0 0 0 -0 0</pose>
        <geometry>
          <mesh>
            <scale>1 1 1</scale>
            <uri>model://odap/src/r2_description/meshes/left_rear_wheel.stl</uri>
          </mesh>
        </geometry>
        <material>
          <script>
            <name>Gazebo/Black</name>
            <uri>file://media/materials/scripts/gazebo.material</uri>
          </script>
        </material>
      </visual>
    </link>
    <joint name='left_steering_joint' type='revolute'>
      <pose relative_to='base_footprint'>0.11922 0.065 0.0336 0 -0 0</pose>
      <parent>base_footprint</parent>
      <child>front_left_steer</child>
      <axis>
        <xyz>0 0 1</xyz>
        <limit>
          <lower>-0.6</lower>
          <upper>0.6</upper>
          <effort>10</effort>
          <velocity>1</velocity>
        </limit>
        <dynamics>
          <spring_reference>0</spring_reference>
          <spring_stiffness>0</spring_stiffness>
        </dynamics>
      </axis>
    </joint>
    <link name='front_left_steer'>
      <pose relative_to='left_steering_joint'>0 0 0 0 -0 0</pose>
      <inertial>
        <pose>0 0 0 1.5708 -0 0</pose>
        <mass>1</mass>
        <inertia>
          <ixx>8.33e-06</ixx>
          <ixy>0</ixy>
          <ixz>0</ixz>
          <iyy>5e-05</iyy>
          <iyz>0</iyz>
          <izz>8.33e-06</izz>
        </inertia>
      </inertial>
      <collision name='front_left_steer_collision'>
        <pose>0 0 0 1.5708 -0 0</pose>
        <geometry>
          <cylinder>
            <length>0.02</length>
            <radius>0.01</radius>
          </cylinder>
        </geometry>
        <surface>
          <contact>
            <ode/>
          </contact>
          <friction>
            <ode/>
          </friction>
        </surface>
      </collision>
      <visual name='front_left_steer_visual'>
        <pose>0 0 0 1.5708 -0 0</pose>
        <geometry>
          <cylinder>
            <length>0.02</length>
            <radius>0.01</radius>
          </cylinder>
        </geometry>
        <material>
          <script>
            <name>Gazebo/Red</name>
            <uri>file://media/materials/scripts/gazebo.material</uri>
          </script>
        </material>
      </visual>
    </link>
    <joint name='left_front_axle' type='revolute'>
      <pose relative_to='front_left_steer'>0.000229 0.0228 0 0 -0 0</pose>
      <parent>front_left_steer</parent>
      <child>left_front_wheel</child>
      <axis>
        <xyz>0 1 0</xyz>
        <limit>
          <lower>-1e+16</lower>
          <upper>1e+16</upper>
        </limit>
        <dynamics>
          <spring_reference>0</spring_reference>
          <spring_stiffness>0</spring_stiffness>
        </dynamics>
      </axis>
    </joint>
    <link name='left_front_wheel'>
      <pose relative_to='left_front_axle'>0 0 0 0 -0 0</pose>
      <inertial>
        <pose>0 0 0 1.5708 -0 0</pose>
        <mass>1</mass>
        <inertia>
          <ixx>9.62948e-05</ixx>
          <ixy>0</ixy>
          <ixz>0</ixz>
          <iyy>0.000578</iyy>
          <iyz>0</iyz>
          <izz>9.62948e-05</izz>
        </inertia>
      </inertial>
      <collision name='left_front_wheel_collision'>
        <pose>0 0 0 1.5708 -0 0</pose>
        <geometry>
          <cylinder>
            <length>0.0267</length>
            <radius>0.034</radius>
          </cylinder>
        </geometry>
        <surface>
          <contact>
            <ode/>
          </contact>
          <friction>
            <ode/>
          </friction>
        </surface>
      </collision>
      <visual name='left_front_wheel_visual'>
        <pose>0 0 0 0 -0 0</pose>
        <geometry>
          <mesh>
            <scale>1 1 1</scale>
            <uri>model://odap/src/r2_description/meshes/front_left_wheel.stl</uri>
          </mesh>
        </geometry>
        <material>
          <script>
            <name>Gazebo/Black</name>
            <uri>file://media/materials/scripts/gazebo.material</uri>
          </script>
        </material>
      </visual>
    </link>
    <joint name='right_rear_axle' type='revolute'>
      <pose relative_to='base_footprint'>-0.11607 -0.08425 0.034 0 -0 0</pose>
      <parent>base_footprint</parent>
      <child>right_rear_wheel</child>
      <axis>
        <xyz>0 1 0</xyz>
        <limit>
          <lower>-1e+16</lower>
          <upper>1e+16</upper>
        </limit>
        <dynamics>
          <spring_reference>0</spring_reference>
          <spring_stiffness>0</spring_stiffness>
        </dynamics>
      </axis>
    </joint>
    <link name='right_rear_wheel'>
      <pose relative_to='right_rear_axle'>0 0 0 0 -0 0</pose>
      <inertial>
        <pose>0 0 0 1.5708 -0 0</pose>
        <mass>1</mass>
        <inertia>
          <ixx>9.62948e-05</ixx>
          <ixy>0</ixy>
          <ixz>0</ixz>
          <iyy>0.000578</iyy>
          <iyz>0</iyz>
          <izz>9.62948e-05</izz>
        </inertia>
      </inertial>
      <collision name='right_rear_wheel_collision'>
        <pose>0 0 0 1.5708 -0 0</pose>
        <geometry>
          <cylinder>
            <length>0.0267</length>
            <radius>0.034</radius>
          </cylinder>
        </geometry>
        <surface>
          <contact>
            <ode/>
          </contact>
          <friction>
            <ode/>
          </friction>
        </surface>
      </collision>
      <visual name='right_rear_wheel_visual'>
        <pose>0 0 0 0 -0 0</pose>
        <geometry>
          <mesh>
            <scale>1 1 1</scale>
            <uri>model://odap/src/r2_description/meshes/right_rear_wheel.STL</uri>
          </mesh>
        </geometry>
        <material>
          <script>
            <name>Gazebo/Black</name>
            <uri>file://media/materials/scripts/gazebo.material</uri>
          </script>
        </material>
      </visual>
    </link>
    <joint name='right_steering_joint' type='revolute'>
      <pose relative_to='base_footprint'>0.11922 -0.065 0.0336 0 -0 0</pose>
      <parent>base_footprint</parent>
      <child>front_right_steer</child>
      <axis>
        <xyz>0 0 1</xyz>
        <limit>
          <lower>-0.6</lower>
          <upper>0.6</upper>
          <effort>10</effort>
          <velocity>1</velocity>
        </limit>
        <dynamics>
          <spring_reference>0</spring_reference>
          <spring_stiffness>0</spring_stiffness>
        </dynamics>
      </axis>
    </joint>
    <link name='front_right_steer'>
      <pose relative_to='right_steering_joint'>0 0 0 0 -0 0</pose>
      <inertial>
        <pose>0 0 0 1.5708 -0 0</pose>
        <mass>1</mass>
        <inertia>
          <ixx>8.33e-06</ixx>
          <ixy>0</ixy>
          <ixz>0</ixz>
          <iyy>5e-05</iyy>
          <iyz>0</iyz>
          <izz>8.33e-06</izz>
        </inertia>
      </inertial>
      <collision name='front_right_steer_collision'>
        <pose>0 0 0 1.5708 -0 0</pose>
        <geometry>
          <cylinder>
            <length>0.02</length>
            <radius>0.01</radius>
          </cylinder>
        </geometry>
        <surface>
          <contact>
            <ode/>
          </contact>
          <friction>
            <ode/>
          </friction>
        </surface>
      </collision>
      <visual name='front_right_steer_visual'>
        <pose>0 0 0 1.5708 -0 0</pose>
        <geometry>
          <cylinder>
            <length>0.02</length>
            <radius>0.01</radius>
          </cylinder>
        </geometry>
        <material>
          <script>
            <name>Gazebo/Red</name>
            <uri>file://media/materials/scripts/gazebo.material</uri>
          </script>
        </material>
      </visual>
    </link>
    <joint name='right_front_axle' type='revolute'>
      <pose relative_to='front_right_steer'>0.000229 -0.0228 0 0 -0 0</pose>
      <parent>front_right_steer</parent>
      <child>right_front_wheel</child>
      <axis>
        <xyz>0 1 0</xyz>
        <limit>
          <lower>-1e+16</lower>
          <upper>1e+16</upper>
        </limit>
        <dynamics>
          <spring_reference>0</spring_reference>
          <spring_stiffness>0</spring_stiffness>
        </dynamics>
      </axis>
    </joint>
    <link name='right_front_wheel'>
      <pose relative_to='right_front_axle'>0 0 0 0 -0 0</pose>
      <inertial>
        <pose>0 0 0 1.5708 -0 0</pose>
        <mass>1</mass>
        <inertia>
          <ixx>9.62948e-05</ixx>
          <ixy>0</ixy>
          <ixz>0</ixz>
          <iyy>0.000578</iyy>
          <iyz>0</iyz>
          <izz>9.62948e-05</izz>
        </inertia>
      </inertial>
      <collision name='right_front_wheel_collision'>
        <pose>0 0 0 1.5708 -0 0</pose>
        <geometry>
          <cylinder>
            <length>0.0267</length>
            <radius>0.034</radius>
          </cylinder>
        </geometry>
        <surface>
          <contact>
            <ode/>
          </contact>
          <friction>
            <ode/>
          </friction>
        </surface>
      </collision>
      <visual name='right_front_wheel_visual'>
        <pose>0 0 0 0 -0 0</pose>
        <geometry>
          <mesh>
            <scale>1 1 1</scale>
            <uri>model://odap/src/r2_description/meshes/front_right_wheel.STL</uri>
          </mesh>
        </geometry>
        <material>
          <script>
            <name>Gazebo/Black</name>
            <uri>file://media/materials/scripts/gazebo.material</uri>
          </script>
        </material>
      </visual>
    </link>
    <static>0</static>
    <plugin name='gazebo_ros_control' filename='libgazebo_ros_control.so'/>
  </model>
</sdf>
