<?xml version="1.0" encoding="utf-8"?>

<robot name= "R2" xmlns:xacro="http://ros.org/wiki/xacro">
    <!--Incluir xacros-macros de enlaces y del lidar-->
    <xacro:include filename="$(find odap)/src/r2_description/urdf/enlaces.xacro"/>
    <xacro:include filename="$(find odap)/src/r2_description/urdf/lidar.xacro"/>
    

<!--imu_link-->
  <link name="imu_link"/>

<!--|Base del Robot-->
  <link name="base_link">
    <inertial>
      <origin xyz="-0.014025 -0.00011707 0.082168" rpy="0 0 0" />
      <mass value="0.52447" />
      <inertia ixx="0.00066245" ixy="-3.1852E-08" ixz="-4.6503E-05"
               iyy="0.0012486" iyz="-3.356E-08"
               izz="0.0018052" />
    </inertial>

    <visual>
      <origin xyz="0 0 0" rpy="0 0 0" />
      <geometry>
        <mesh filename="package://odap/src/r2_description/meshes/base_link.STL" />
      </geometry>
      <material name="">
        <color rgba="0 0.62745 0.23529 1" />
      </material>
    </visual>

    <collision>
      <origin xyz="0 0 0" rpy="0 0 0" />
      <geometry>
        <mesh filename="package://odap/src/r2_description/meshes/base_link.STL" />
      </geometry>
    </collision>
  </link>

<!--|Steerings-->
<!--*Steering Izquierdo-->
    <xacro:steering prefix="front_left" radius="0.01" length="0.02" mass="1.0" mesh="" flag="0"/>
<!--*Steering Derecho-->
    <xacro:steering prefix="front_right" radius="0.01" length="0.02" mass="1.0" mesh="" flag="0"/>
<!--!Joints Steerings-->
<!--*Joint Steering Izquierdo-->
    <joint name="left_steering_joint" type="revolute">
        <origin xyz="0.11922 0.065 0.0121" rpy="0 0 0" />
        <parent link="base_link" />
        <child link="front_left_steer" />
        <axis xyz="0 0 1" />
        <limit
            lower="-0.6"
            upper="0.6"
            effort="10"
            velocity="1" />
    </joint>
<!--*Joint Steering Derecho-->
    <joint name="right_steering_joint" type="revolute">
        <origin xyz="0.11922 -0.065 0.0121" rpy="0 0 0" />
        <parent link="base_link" />
        <child link="front_right_steer" />
        <axis xyz="0 0 1" />
        <limit
            lower="-0.6"
            upper="0.6"
            effort="10"
            velocity="1" />
    </joint>

<!--|Llantas-->
<!--!Llantas Frontales-->
<!--*Llanta Frontal Izquierda-->
    <xacro:wheel prefix="left_front" radius="0.034" length="0.0267" mass="1.0" mesh="package://odap/src/r2_description/meshes/front_left_wheel.stl" flag="1"/>
<!--*Llanta Frontal Derecha-->
    <xacro:wheel prefix="right_front" radius="0.034" length="0.0267" mass="1.0" mesh="package://odap/src/r2_description/meshes/front_right_wheel.STL" flag="1"/>
<!--!Joints Steering y Llantas Frontales--> <!--AGUAS EJE DE ROTACIÓN EN NEGATIVO-->
<!--*Direccionador izquierdo y llanta izquierda-->
    <joint name="left_front_axle" type="continuous">
        <origin xyz="0.00022897 0.0228 0.0" rpy="0 0 0" />
        <parent link="front_left_steer" />
        <child link="left_front_wheel" />
        <axis xyz="0 1 0" />
    </joint>

<!--*Direccionador derecho y llanta derecha-->
    <joint name="right_front_axle" type="continuous">
        <origin xyz="0.00022897 -0.0228 0.0" rpy="0 0 0" />
        <parent link="front_right_steer" />
        <child link="right_front_wheel" />
        <axis xyz="0 1 0" />
    </joint>

<!--!Llantas Traseras-->
<!--*Llanta Trasera Izquierda-->
    <xacro:wheel prefix="left_rear" radius="0.034" length="0.0267" mass="1.0" mesh="package://odap/src/r2_description/meshes/left_rear_wheel.stl" flag="1"/>
<!--*Llanta Trasera Derecha-->
    <xacro:wheel prefix="right_rear" radius="0.034" length="0.0267" mass="1.0" mesh="package://odap/src/r2_description/meshes/right_rear_wheel.STL" flag="1"/>
<!--!Joints Base y Llantas Traseras-->
<!--*Base y Llanta Izquierda-->
    <joint name="left_rear_axle" type="continuous">
        <origin xyz="-0.11607 0.08425 0.0125" rpy="0 0 0" />
        <parent link="base_link" />
        <child link="left_rear_wheel" />
        <axis xyz="0 1 0" />
    </joint>
<!--*Base y Llanta Izquierda-->
    <joint name="right_rear_axle" type="continuous">
        <origin xyz="-0.11607 -0.08425 0.0125" rpy="0 0 0" />
        <parent link="base_link" />
        <child link="right_rear_wheel" />
        <axis xyz="0 1 0" />
    </joint>

<!--|Transformaciones Finales-->
<!--Joint Fijo entre imu_link y base_link-->
    <joint name="base_imu" type="fixed">
        <parent link="base_link"/>
        <child link="imu_link"/>
        <origin xyz="-0.05 0.0 0.05" rpy="0 3.1415 1.5707"/>
    </joint>

<!--Joint Fijo entre base_link y base_footprint-->
    <link name="base_footprint"/>
        <joint name="base_joint" type="fixed">
        <parent link="base_footprint"/>
        <child link="base_link"/>
        <origin xyz="0.0 0.0 0.0215" rpy="0 0 0"/>
    </joint>

<!--|Colocar Transmisiones-->
<!--Steerings-->
    <xacro:steering_transmission prefix="left" joint="left_steering_joint"/>
    <xacro:steering_transmission prefix="right" joint="right_steering_joint"/>

<!--Llantas-->
    <xacro:wheel_transmission side="left" location="front" joint="left_front_axle"/>
    <xacro:wheel_transmission side="right" location="front" joint="right_front_axle"/>
    <xacro:wheel_transmission side="left" location="rear" joint="left_rear_axle"/>
    <xacro:wheel_transmission side="right" location="rear" joint="right_rear_axle"/>

<!--|Colocar el LiDAR-->
    <joint name="lidarGlue" type="fixed">
        <parent link="base_link"/>
        <child link="laz_base"/>
        <origin xyz="0.012548 0.0 0.105"/>
    </joint>

<!--|Elementos para GAZEBO-->
  <gazebo>
    <plugin name="gazebo_ros_control" filename="libgazebo_ros_control.so">
      <!--| <robotNamespace>/odap_R2</robotNamespace> -->
    </plugin>
  </gazebo>

<!--*Colores para los Links-->
    <!--Color Base Link-->
    <gazebo reference="base_link">
        <material>Gazebo/Green</material>
    </gazebo>

    <!--Colores llantas-->
    <gazebo reference="left_front_wheel">
        <material>Gazebo/Black</material>
    </gazebo>
    <gazebo reference="right_front_wheel">
        <material>Gazebo/Black</material>
    </gazebo>
    <gazebo reference="left_rear_wheel">
        <material>Gazebo/Black</material>
    </gazebo>
    <gazebo reference="right_rear_wheel">
        <material>Gazebo/Black</material>
    </gazebo>

    <!--Colores Steerings-->
    <gazebo reference="front_left_steer">
        <material>Gazebo/Red</material>
    </gazebo>
    <gazebo reference="front_right_steer">
        <material>Gazebo/Red</material>
    </gazebo>

</robot>